using System;
using System.Collections.Generic;
using System.IO;
using System.Linq;
using System.Text;
using System.Threading.Tasks;

namespace ByteBank
{
    class Program
    {
        static void Main(string[] args)
        {
            try
            {
                CarregarContas();
            }
            catch (Exception)
            {
                Console.WriteLine("CATCH NO METODO MAIN");
            }

            Console.ReadLine();
        }

        private static void CarregarContas()
        {
            // Debaixo dos panos o using chamou o método Dispose, por isso não precisamos explicitar a chamada no código
            // É como se a máquina virtual "transformasse" o using em um try catch/finally
            using (LeitorDeArquivo leitor = new LeitorDeArquivo("teste.txt"))
            {
                leitor.LerProximaLinha();
            }

            // -----------------------------------------------------------
            // Mesma lógica, só que com uma construção e sintaxe diferente
            // -----------------------------------------------------------

            //LeitorDeArquivo leitor = null;

            //try // Try é usado sempre com catch ou finally
            //{
            //    leitor = new LeitorDeArquivo("contas.txt");

            //    leitor.LerProximaLinha();
            //    leitor.LerProximaLinha();
            //    leitor.LerProximaLinha();
            //}
            //catch (IOException)
            //{
            //    Console.WriteLine("Exceção do tipo IOException capturada e tratada!");
            //}
            //finally // Sempre é executado, seja depois do try ou do catch
            //{
            //    Console.WriteLine("Executando o finally");
            //    if (leitor != null)
            //    {
            //        leitor.Fechar();
            //    }
            //}
        }

        private static void TestaInnerException()
        {
            try
            {
                ContaCorrente conta1 = new ContaCorrente(1234, 4567899);
                ContaCorrente conta2 = new ContaCorrente(2434, 4567855);

                // conta1.Transferir(10000, conta2);
                conta1.Sacar(1000);
            }
            catch (OperacaoFinanceiraException e)
            {
                Console.WriteLine(e.Message);
                Console.WriteLine(e.StackTrace);

                //Console.WriteLine("Informações da Inner Exception:");
                //Console.WriteLine(e.InnerException.Message);
                //Console.WriteLine(e.InnerException.StackTrace);
            }
        }

        // Teste com a cadeia de chamada:
        // Metodo -> TestaDivisao -> Dividir
        private static void Metodo()
        {
            TestaDivisao(0);
        }

        private static void TestaDivisao(int divisor)
        {
            int resultado = Dividir(10, divisor);
            Console.WriteLine("Resultado da divisão de 10 por " + divisor + " é " + resultado);
        }

        private static int Dividir(int numero, int divisor)
        {
            try
            {
                return numero / divisor;
            }
            catch (DivideByZeroException)
            {
                Console.WriteLine("Exceção com número=" + numero + " e divisor=" + divisor);
                throw;
            }
        }
    }
}